INFO 2022-10-01 11:05:01,944 file_cache is only supported with oauth2client<4.0.0
INFO 2022-10-01 11:05:02,206 Attempting refresh to obtain initial access_token
INFO 2022-10-01 11:05:02,241 Refreshing access_token
ERROR 2022-10-01 11:05:04,285 Internal Server Error: /canal_service/
Traceback (most recent call last):
  File "/usr/local/lib/python3.9/site-packages/django/db/backends/base/base.py", line 219, in ensure_connection
    self.connect()
  File "/usr/local/lib/python3.9/site-packages/django/utils/asyncio.py", line 26, in inner
    return func(*args, **kwargs)
  File "/usr/local/lib/python3.9/site-packages/django/db/backends/base/base.py", line 200, in connect
    self.connection = self.get_new_connection(conn_params)
  File "/usr/local/lib/python3.9/site-packages/django/utils/asyncio.py", line 26, in inner
    return func(*args, **kwargs)
  File "/usr/local/lib/python3.9/site-packages/django/db/backends/postgresql/base.py", line 187, in get_new_connection
    connection = Database.connect(**conn_params)
  File "/usr/local/lib/python3.9/site-packages/psycopg2/__init__.py", line 122, in connect
    conn = _connect(dsn, connection_factory=connection_factory, **kwasync)
psycopg2.OperationalError: connection to server at "localhost" (127.0.0.1), port 5432 failed: Connection refused
	Is the server running on that host and accepting TCP/IP connections?
connection to server at "localhost" (::1), port 5432 failed: Cannot assign requested address
	Is the server running on that host and accepting TCP/IP connections?


The above exception was the direct cause of the following exception:

Traceback (most recent call last):
  File "/usr/local/lib/python3.9/site-packages/django/core/handlers/exception.py", line 47, in inner
    response = get_response(request)
  File "/usr/local/lib/python3.9/site-packages/django/core/handlers/base.py", line 181, in _get_response
    response = wrapped_callback(request, *callback_args, **callback_kwargs)
  File "/usr/local/lib/python3.9/site-packages/django/views/generic/base.py", line 70, in view
    return self.dispatch(request, *args, **kwargs)
  File "/usr/local/lib/python3.9/site-packages/django/views/generic/base.py", line 98, in dispatch
    return handler(request, *args, **kwargs)
  File "/usr/local/lib/python3.9/site-packages/django/views/generic/list.py", line 157, in get
    context = self.get_context_data()
  File "/code/table_app/views.py", line 23, in get_context_data
    ResultTable.objects.all().delete()
  File "/usr/local/lib/python3.9/site-packages/django/db/models/query.py", line 746, in delete
    deleted, _rows_count = collector.delete()
  File "/usr/local/lib/python3.9/site-packages/django/db/models/deletion.py", line 400, in delete
    with transaction.atomic(using=self.using, savepoint=False):
  File "/usr/local/lib/python3.9/site-packages/django/db/transaction.py", line 189, in __enter__
    if not connection.get_autocommit():
  File "/usr/local/lib/python3.9/site-packages/django/db/backends/base/base.py", line 389, in get_autocommit
    self.ensure_connection()
  File "/usr/local/lib/python3.9/site-packages/django/utils/asyncio.py", line 26, in inner
    return func(*args, **kwargs)
  File "/usr/local/lib/python3.9/site-packages/django/db/backends/base/base.py", line 219, in ensure_connection
    self.connect()
  File "/usr/local/lib/python3.9/site-packages/django/db/utils.py", line 90, in __exit__
    raise dj_exc_value.with_traceback(traceback) from exc_value
  File "/usr/local/lib/python3.9/site-packages/django/db/backends/base/base.py", line 219, in ensure_connection
    self.connect()
  File "/usr/local/lib/python3.9/site-packages/django/utils/asyncio.py", line 26, in inner
    return func(*args, **kwargs)
  File "/usr/local/lib/python3.9/site-packages/django/db/backends/base/base.py", line 200, in connect
    self.connection = self.get_new_connection(conn_params)
  File "/usr/local/lib/python3.9/site-packages/django/utils/asyncio.py", line 26, in inner
    return func(*args, **kwargs)
  File "/usr/local/lib/python3.9/site-packages/django/db/backends/postgresql/base.py", line 187, in get_new_connection
    connection = Database.connect(**conn_params)
  File "/usr/local/lib/python3.9/site-packages/psycopg2/__init__.py", line 122, in connect
    conn = _connect(dsn, connection_factory=connection_factory, **kwasync)
django.db.utils.OperationalError: connection to server at "localhost" (127.0.0.1), port 5432 failed: Connection refused
	Is the server running on that host and accepting TCP/IP connections?
connection to server at "localhost" (::1), port 5432 failed: Cannot assign requested address
	Is the server running on that host and accepting TCP/IP connections?

WARNING 2022-10-01 11:05:06,843 Not Found: /favicon.ico
INFO 2022-10-01 11:07:54,976 file_cache is only supported with oauth2client<4.0.0
INFO 2022-10-01 11:07:55,257 Attempting refresh to obtain initial access_token
INFO 2022-10-01 11:07:55,292 Refreshing access_token
ERROR 2022-10-01 11:07:56,293 Internal Server Error: /canal_service/
Traceback (most recent call last):
  File "/usr/local/lib/python3.9/site-packages/django/db/backends/base/base.py", line 219, in ensure_connection
    self.connect()
  File "/usr/local/lib/python3.9/site-packages/django/utils/asyncio.py", line 26, in inner
    return func(*args, **kwargs)
  File "/usr/local/lib/python3.9/site-packages/django/db/backends/base/base.py", line 200, in connect
    self.connection = self.get_new_connection(conn_params)
  File "/usr/local/lib/python3.9/site-packages/django/utils/asyncio.py", line 26, in inner
    return func(*args, **kwargs)
  File "/usr/local/lib/python3.9/site-packages/django/db/backends/postgresql/base.py", line 187, in get_new_connection
    connection = Database.connect(**conn_params)
  File "/usr/local/lib/python3.9/site-packages/psycopg2/__init__.py", line 122, in connect
    conn = _connect(dsn, connection_factory=connection_factory, **kwasync)
psycopg2.OperationalError: connection to server at "0.0.0.0", port 5432 failed: Connection refused
	Is the server running on that host and accepting TCP/IP connections?


The above exception was the direct cause of the following exception:

Traceback (most recent call last):
  File "/usr/local/lib/python3.9/site-packages/django/core/handlers/exception.py", line 47, in inner
    response = get_response(request)
  File "/usr/local/lib/python3.9/site-packages/django/core/handlers/base.py", line 181, in _get_response
    response = wrapped_callback(request, *callback_args, **callback_kwargs)
  File "/usr/local/lib/python3.9/site-packages/django/views/generic/base.py", line 70, in view
    return self.dispatch(request, *args, **kwargs)
  File "/usr/local/lib/python3.9/site-packages/django/views/generic/base.py", line 98, in dispatch
    return handler(request, *args, **kwargs)
  File "/usr/local/lib/python3.9/site-packages/django/views/generic/list.py", line 157, in get
    context = self.get_context_data()
  File "/code/table_app/views.py", line 23, in get_context_data
    ResultTable.objects.all().delete()
  File "/usr/local/lib/python3.9/site-packages/django/db/models/query.py", line 746, in delete
    deleted, _rows_count = collector.delete()
  File "/usr/local/lib/python3.9/site-packages/django/db/models/deletion.py", line 400, in delete
    with transaction.atomic(using=self.using, savepoint=False):
  File "/usr/local/lib/python3.9/site-packages/django/db/transaction.py", line 189, in __enter__
    if not connection.get_autocommit():
  File "/usr/local/lib/python3.9/site-packages/django/db/backends/base/base.py", line 389, in get_autocommit
    self.ensure_connection()
  File "/usr/local/lib/python3.9/site-packages/django/utils/asyncio.py", line 26, in inner
    return func(*args, **kwargs)
  File "/usr/local/lib/python3.9/site-packages/django/db/backends/base/base.py", line 219, in ensure_connection
    self.connect()
  File "/usr/local/lib/python3.9/site-packages/django/db/utils.py", line 90, in __exit__
    raise dj_exc_value.with_traceback(traceback) from exc_value
  File "/usr/local/lib/python3.9/site-packages/django/db/backends/base/base.py", line 219, in ensure_connection
    self.connect()
  File "/usr/local/lib/python3.9/site-packages/django/utils/asyncio.py", line 26, in inner
    return func(*args, **kwargs)
  File "/usr/local/lib/python3.9/site-packages/django/db/backends/base/base.py", line 200, in connect
    self.connection = self.get_new_connection(conn_params)
  File "/usr/local/lib/python3.9/site-packages/django/utils/asyncio.py", line 26, in inner
    return func(*args, **kwargs)
  File "/usr/local/lib/python3.9/site-packages/django/db/backends/postgresql/base.py", line 187, in get_new_connection
    connection = Database.connect(**conn_params)
  File "/usr/local/lib/python3.9/site-packages/psycopg2/__init__.py", line 122, in connect
    conn = _connect(dsn, connection_factory=connection_factory, **kwasync)
django.db.utils.OperationalError: connection to server at "0.0.0.0", port 5432 failed: Connection refused
	Is the server running on that host and accepting TCP/IP connections?

INFO 2022-10-01 11:12:08,667 file_cache is only supported with oauth2client<4.0.0
INFO 2022-10-01 11:12:08,901 Attempting refresh to obtain initial access_token
INFO 2022-10-01 11:12:08,946 Refreshing access_token
ERROR 2022-10-01 11:12:10,158 Internal Server Error: /canal_service/
Traceback (most recent call last):
  File "/usr/local/lib/python3.9/site-packages/django/db/backends/base/base.py", line 219, in ensure_connection
    self.connect()
  File "/usr/local/lib/python3.9/site-packages/django/utils/asyncio.py", line 26, in inner
    return func(*args, **kwargs)
  File "/usr/local/lib/python3.9/site-packages/django/db/backends/base/base.py", line 200, in connect
    self.connection = self.get_new_connection(conn_params)
  File "/usr/local/lib/python3.9/site-packages/django/utils/asyncio.py", line 26, in inner
    return func(*args, **kwargs)
  File "/usr/local/lib/python3.9/site-packages/django/db/backends/postgresql/base.py", line 187, in get_new_connection
    connection = Database.connect(**conn_params)
  File "/usr/local/lib/python3.9/site-packages/psycopg2/__init__.py", line 122, in connect
    conn = _connect(dsn, connection_factory=connection_factory, **kwasync)
psycopg2.OperationalError: connection to server at "localhost" (127.0.0.1), port 5432 failed: Connection refused
	Is the server running on that host and accepting TCP/IP connections?
connection to server at "localhost" (::1), port 5432 failed: Cannot assign requested address
	Is the server running on that host and accepting TCP/IP connections?


The above exception was the direct cause of the following exception:

Traceback (most recent call last):
  File "/usr/local/lib/python3.9/site-packages/django/core/handlers/exception.py", line 47, in inner
    response = get_response(request)
  File "/usr/local/lib/python3.9/site-packages/django/core/handlers/base.py", line 181, in _get_response
    response = wrapped_callback(request, *callback_args, **callback_kwargs)
  File "/usr/local/lib/python3.9/site-packages/django/views/generic/base.py", line 70, in view
    return self.dispatch(request, *args, **kwargs)
  File "/usr/local/lib/python3.9/site-packages/django/views/generic/base.py", line 98, in dispatch
    return handler(request, *args, **kwargs)
  File "/usr/local/lib/python3.9/site-packages/django/views/generic/list.py", line 157, in get
    context = self.get_context_data()
  File "/code/table_app/views.py", line 23, in get_context_data
    ResultTable.objects.all().delete()
  File "/usr/local/lib/python3.9/site-packages/django/db/models/query.py", line 746, in delete
    deleted, _rows_count = collector.delete()
  File "/usr/local/lib/python3.9/site-packages/django/db/models/deletion.py", line 400, in delete
    with transaction.atomic(using=self.using, savepoint=False):
  File "/usr/local/lib/python3.9/site-packages/django/db/transaction.py", line 189, in __enter__
    if not connection.get_autocommit():
  File "/usr/local/lib/python3.9/site-packages/django/db/backends/base/base.py", line 389, in get_autocommit
    self.ensure_connection()
  File "/usr/local/lib/python3.9/site-packages/django/utils/asyncio.py", line 26, in inner
    return func(*args, **kwargs)
  File "/usr/local/lib/python3.9/site-packages/django/db/backends/base/base.py", line 219, in ensure_connection
    self.connect()
  File "/usr/local/lib/python3.9/site-packages/django/db/utils.py", line 90, in __exit__
    raise dj_exc_value.with_traceback(traceback) from exc_value
  File "/usr/local/lib/python3.9/site-packages/django/db/backends/base/base.py", line 219, in ensure_connection
    self.connect()
  File "/usr/local/lib/python3.9/site-packages/django/utils/asyncio.py", line 26, in inner
    return func(*args, **kwargs)
  File "/usr/local/lib/python3.9/site-packages/django/db/backends/base/base.py", line 200, in connect
    self.connection = self.get_new_connection(conn_params)
  File "/usr/local/lib/python3.9/site-packages/django/utils/asyncio.py", line 26, in inner
    return func(*args, **kwargs)
  File "/usr/local/lib/python3.9/site-packages/django/db/backends/postgresql/base.py", line 187, in get_new_connection
    connection = Database.connect(**conn_params)
  File "/usr/local/lib/python3.9/site-packages/psycopg2/__init__.py", line 122, in connect
    conn = _connect(dsn, connection_factory=connection_factory, **kwasync)
django.db.utils.OperationalError: connection to server at "localhost" (127.0.0.1), port 5432 failed: Connection refused
	Is the server running on that host and accepting TCP/IP connections?
connection to server at "localhost" (::1), port 5432 failed: Cannot assign requested address
	Is the server running on that host and accepting TCP/IP connections?

INFO 2022-10-01 11:28:25,891 file_cache is only supported with oauth2client<4.0.0
INFO 2022-10-01 11:28:26,211 Attempting refresh to obtain initial access_token
INFO 2022-10-01 11:28:26,246 Refreshing access_token
ERROR 2022-10-01 11:28:27,862 Internal Server Error: /canal_service/
Traceback (most recent call last):
  File "/usr/local/lib/python3.9/site-packages/django/db/backends/base/base.py", line 219, in ensure_connection
    self.connect()
  File "/usr/local/lib/python3.9/site-packages/django/utils/asyncio.py", line 26, in inner
    return func(*args, **kwargs)
  File "/usr/local/lib/python3.9/site-packages/django/db/backends/base/base.py", line 200, in connect
    self.connection = self.get_new_connection(conn_params)
  File "/usr/local/lib/python3.9/site-packages/django/utils/asyncio.py", line 26, in inner
    return func(*args, **kwargs)
  File "/usr/local/lib/python3.9/site-packages/django/db/backends/postgresql/base.py", line 187, in get_new_connection
    connection = Database.connect(**conn_params)
  File "/usr/local/lib/python3.9/site-packages/psycopg2/__init__.py", line 122, in connect
    conn = _connect(dsn, connection_factory=connection_factory, **kwasync)
psycopg2.OperationalError: connection to server at "0.0.0.0", port 7733 failed: Connection refused
	Is the server running on that host and accepting TCP/IP connections?


The above exception was the direct cause of the following exception:

Traceback (most recent call last):
  File "/usr/local/lib/python3.9/site-packages/django/core/handlers/exception.py", line 47, in inner
    response = get_response(request)
  File "/usr/local/lib/python3.9/site-packages/django/core/handlers/base.py", line 181, in _get_response
    response = wrapped_callback(request, *callback_args, **callback_kwargs)
  File "/usr/local/lib/python3.9/site-packages/django/views/generic/base.py", line 70, in view
    return self.dispatch(request, *args, **kwargs)
  File "/usr/local/lib/python3.9/site-packages/django/views/generic/base.py", line 98, in dispatch
    return handler(request, *args, **kwargs)
  File "/usr/local/lib/python3.9/site-packages/django/views/generic/list.py", line 157, in get
    context = self.get_context_data()
  File "/code/table_app/views.py", line 23, in get_context_data
    ResultTable.objects.all().delete()
  File "/usr/local/lib/python3.9/site-packages/django/db/models/query.py", line 746, in delete
    deleted, _rows_count = collector.delete()
  File "/usr/local/lib/python3.9/site-packages/django/db/models/deletion.py", line 400, in delete
    with transaction.atomic(using=self.using, savepoint=False):
  File "/usr/local/lib/python3.9/site-packages/django/db/transaction.py", line 189, in __enter__
    if not connection.get_autocommit():
  File "/usr/local/lib/python3.9/site-packages/django/db/backends/base/base.py", line 389, in get_autocommit
    self.ensure_connection()
  File "/usr/local/lib/python3.9/site-packages/django/utils/asyncio.py", line 26, in inner
    return func(*args, **kwargs)
  File "/usr/local/lib/python3.9/site-packages/django/db/backends/base/base.py", line 219, in ensure_connection
    self.connect()
  File "/usr/local/lib/python3.9/site-packages/django/db/utils.py", line 90, in __exit__
    raise dj_exc_value.with_traceback(traceback) from exc_value
  File "/usr/local/lib/python3.9/site-packages/django/db/backends/base/base.py", line 219, in ensure_connection
    self.connect()
  File "/usr/local/lib/python3.9/site-packages/django/utils/asyncio.py", line 26, in inner
    return func(*args, **kwargs)
  File "/usr/local/lib/python3.9/site-packages/django/db/backends/base/base.py", line 200, in connect
    self.connection = self.get_new_connection(conn_params)
  File "/usr/local/lib/python3.9/site-packages/django/utils/asyncio.py", line 26, in inner
    return func(*args, **kwargs)
  File "/usr/local/lib/python3.9/site-packages/django/db/backends/postgresql/base.py", line 187, in get_new_connection
    connection = Database.connect(**conn_params)
  File "/usr/local/lib/python3.9/site-packages/psycopg2/__init__.py", line 122, in connect
    conn = _connect(dsn, connection_factory=connection_factory, **kwasync)
django.db.utils.OperationalError: connection to server at "0.0.0.0", port 7733 failed: Connection refused
	Is the server running on that host and accepting TCP/IP connections?

INFO 2022-10-01 11:30:22,397 file_cache is only supported with oauth2client<4.0.0
INFO 2022-10-01 11:30:22,567 Attempting refresh to obtain initial access_token
INFO 2022-10-01 11:30:22,601 Refreshing access_token
INFO 2022-10-01 11:31:22,689 file_cache is only supported with oauth2client<4.0.0
INFO 2022-10-01 11:31:22,859 Attempting refresh to obtain initial access_token
INFO 2022-10-01 11:31:22,893 Refreshing access_token
INFO 2022-10-01 11:32:24,070 file_cache is only supported with oauth2client<4.0.0
INFO 2022-10-01 11:32:24,284 Attempting refresh to obtain initial access_token
INFO 2022-10-01 11:32:24,320 Refreshing access_token
INFO 2022-10-01 11:33:25,546 file_cache is only supported with oauth2client<4.0.0
INFO 2022-10-01 11:33:25,729 Attempting refresh to obtain initial access_token
INFO 2022-10-01 11:33:25,764 Refreshing access_token
INFO 2022-10-01 11:34:32,079 file_cache is only supported with oauth2client<4.0.0
INFO 2022-10-01 11:34:32,294 Attempting refresh to obtain initial access_token
INFO 2022-10-01 11:34:32,341 Refreshing access_token
INFO 2022-10-01 11:35:37,372 file_cache is only supported with oauth2client<4.0.0
INFO 2022-10-01 11:35:37,530 Attempting refresh to obtain initial access_token
INFO 2022-10-01 11:35:37,565 Refreshing access_token
ERROR 2022-10-01 11:35:39,426 Internal Server Error: /canal_service/
Traceback (most recent call last):
  File "/usr/local/lib/python3.9/site-packages/django/db/backends/base/base.py", line 219, in ensure_connection
    self.connect()
  File "/usr/local/lib/python3.9/site-packages/django/utils/asyncio.py", line 26, in inner
    return func(*args, **kwargs)
  File "/usr/local/lib/python3.9/site-packages/django/db/backends/base/base.py", line 200, in connect
    self.connection = self.get_new_connection(conn_params)
  File "/usr/local/lib/python3.9/site-packages/django/utils/asyncio.py", line 26, in inner
    return func(*args, **kwargs)
  File "/usr/local/lib/python3.9/site-packages/django/db/backends/postgresql/base.py", line 187, in get_new_connection
    connection = Database.connect(**conn_params)
  File "/usr/local/lib/python3.9/site-packages/psycopg2/__init__.py", line 122, in connect
    conn = _connect(dsn, connection_factory=connection_factory, **kwasync)
psycopg2.OperationalError: connection to server at "db" (192.168.176.2), port 5432 failed: FATAL:  database "canal_service_test" does not exist


The above exception was the direct cause of the following exception:

Traceback (most recent call last):
  File "/usr/local/lib/python3.9/site-packages/django/core/handlers/exception.py", line 47, in inner
    response = get_response(request)
  File "/usr/local/lib/python3.9/site-packages/django/core/handlers/base.py", line 181, in _get_response
    response = wrapped_callback(request, *callback_args, **callback_kwargs)
  File "/usr/local/lib/python3.9/site-packages/django/views/generic/base.py", line 70, in view
    return self.dispatch(request, *args, **kwargs)
  File "/usr/local/lib/python3.9/site-packages/django/views/generic/base.py", line 98, in dispatch
    return handler(request, *args, **kwargs)
  File "/usr/local/lib/python3.9/site-packages/django/views/generic/list.py", line 157, in get
    context = self.get_context_data()
  File "/code/table_app/views.py", line 23, in get_context_data
    ResultTable.objects.all().delete()
  File "/usr/local/lib/python3.9/site-packages/django/db/models/query.py", line 746, in delete
    deleted, _rows_count = collector.delete()
  File "/usr/local/lib/python3.9/site-packages/django/db/models/deletion.py", line 400, in delete
    with transaction.atomic(using=self.using, savepoint=False):
  File "/usr/local/lib/python3.9/site-packages/django/db/transaction.py", line 189, in __enter__
    if not connection.get_autocommit():
  File "/usr/local/lib/python3.9/site-packages/django/db/backends/base/base.py", line 389, in get_autocommit
    self.ensure_connection()
  File "/usr/local/lib/python3.9/site-packages/django/utils/asyncio.py", line 26, in inner
    return func(*args, **kwargs)
  File "/usr/local/lib/python3.9/site-packages/django/db/backends/base/base.py", line 219, in ensure_connection
    self.connect()
  File "/usr/local/lib/python3.9/site-packages/django/db/utils.py", line 90, in __exit__
    raise dj_exc_value.with_traceback(traceback) from exc_value
  File "/usr/local/lib/python3.9/site-packages/django/db/backends/base/base.py", line 219, in ensure_connection
    self.connect()
  File "/usr/local/lib/python3.9/site-packages/django/utils/asyncio.py", line 26, in inner
    return func(*args, **kwargs)
  File "/usr/local/lib/python3.9/site-packages/django/db/backends/base/base.py", line 200, in connect
    self.connection = self.get_new_connection(conn_params)
  File "/usr/local/lib/python3.9/site-packages/django/utils/asyncio.py", line 26, in inner
    return func(*args, **kwargs)
  File "/usr/local/lib/python3.9/site-packages/django/db/backends/postgresql/base.py", line 187, in get_new_connection
    connection = Database.connect(**conn_params)
  File "/usr/local/lib/python3.9/site-packages/psycopg2/__init__.py", line 122, in connect
    conn = _connect(dsn, connection_factory=connection_factory, **kwasync)
django.db.utils.OperationalError: connection to server at "db" (192.168.176.2), port 5432 failed: FATAL:  database "canal_service_test" does not exist

ERROR 2022-10-01 11:39:46,061 Invalid HTTP_HOST header: '192.168.100.71:8080'. You may need to add '192.168.100.71' to ALLOWED_HOSTS.
WARNING 2022-10-01 11:39:46,095 Bad Request: /
ERROR 2022-10-01 11:39:52,712 Invalid HTTP_HOST header: '192.168.100.71'. You may need to add '192.168.100.71' to ALLOWED_HOSTS.
WARNING 2022-10-01 11:39:52,745 Bad Request: /HNAP1/
INFO 2022-10-01 12:00:35,938 file_cache is only supported with oauth2client<4.0.0
INFO 2022-10-01 12:00:36,213 Attempting refresh to obtain initial access_token
INFO 2022-10-01 12:00:36,249 Refreshing access_token
ERROR 2022-10-01 12:00:37,810 Internal Server Error: /canal_service/
Traceback (most recent call last):
  File "/usr/local/lib/python3.9/site-packages/django/db/backends/base/base.py", line 219, in ensure_connection
    self.connect()
  File "/usr/local/lib/python3.9/site-packages/django/utils/asyncio.py", line 26, in inner
    return func(*args, **kwargs)
  File "/usr/local/lib/python3.9/site-packages/django/db/backends/base/base.py", line 200, in connect
    self.connection = self.get_new_connection(conn_params)
  File "/usr/local/lib/python3.9/site-packages/django/utils/asyncio.py", line 26, in inner
    return func(*args, **kwargs)
  File "/usr/local/lib/python3.9/site-packages/django/db/backends/postgresql/base.py", line 187, in get_new_connection
    connection = Database.connect(**conn_params)
  File "/usr/local/lib/python3.9/site-packages/psycopg2/__init__.py", line 122, in connect
    conn = _connect(dsn, connection_factory=connection_factory, **kwasync)
psycopg2.OperationalError: connection to server at "localhost" (127.0.0.1), port 5432 failed: Connection refused
	Is the server running on that host and accepting TCP/IP connections?
connection to server at "localhost" (::1), port 5432 failed: Cannot assign requested address
	Is the server running on that host and accepting TCP/IP connections?


The above exception was the direct cause of the following exception:

Traceback (most recent call last):
  File "/usr/local/lib/python3.9/site-packages/django/core/handlers/exception.py", line 47, in inner
    response = get_response(request)
  File "/usr/local/lib/python3.9/site-packages/django/core/handlers/base.py", line 181, in _get_response
    response = wrapped_callback(request, *callback_args, **callback_kwargs)
  File "/usr/local/lib/python3.9/site-packages/django/views/generic/base.py", line 70, in view
    return self.dispatch(request, *args, **kwargs)
  File "/usr/local/lib/python3.9/site-packages/django/views/generic/base.py", line 98, in dispatch
    return handler(request, *args, **kwargs)
  File "/usr/local/lib/python3.9/site-packages/django/views/generic/list.py", line 157, in get
    context = self.get_context_data()
  File "/code/table_app/views.py", line 23, in get_context_data
    ResultTable.objects.all().delete()
  File "/usr/local/lib/python3.9/site-packages/django/db/models/query.py", line 746, in delete
    deleted, _rows_count = collector.delete()
  File "/usr/local/lib/python3.9/site-packages/django/db/models/deletion.py", line 400, in delete
    with transaction.atomic(using=self.using, savepoint=False):
  File "/usr/local/lib/python3.9/site-packages/django/db/transaction.py", line 189, in __enter__
    if not connection.get_autocommit():
  File "/usr/local/lib/python3.9/site-packages/django/db/backends/base/base.py", line 389, in get_autocommit
    self.ensure_connection()
  File "/usr/local/lib/python3.9/site-packages/django/utils/asyncio.py", line 26, in inner
    return func(*args, **kwargs)
  File "/usr/local/lib/python3.9/site-packages/django/db/backends/base/base.py", line 219, in ensure_connection
    self.connect()
  File "/usr/local/lib/python3.9/site-packages/django/db/utils.py", line 90, in __exit__
    raise dj_exc_value.with_traceback(traceback) from exc_value
  File "/usr/local/lib/python3.9/site-packages/django/db/backends/base/base.py", line 219, in ensure_connection
    self.connect()
  File "/usr/local/lib/python3.9/site-packages/django/utils/asyncio.py", line 26, in inner
    return func(*args, **kwargs)
  File "/usr/local/lib/python3.9/site-packages/django/db/backends/base/base.py", line 200, in connect
    self.connection = self.get_new_connection(conn_params)
  File "/usr/local/lib/python3.9/site-packages/django/utils/asyncio.py", line 26, in inner
    return func(*args, **kwargs)
  File "/usr/local/lib/python3.9/site-packages/django/db/backends/postgresql/base.py", line 187, in get_new_connection
    connection = Database.connect(**conn_params)
  File "/usr/local/lib/python3.9/site-packages/psycopg2/__init__.py", line 122, in connect
    conn = _connect(dsn, connection_factory=connection_factory, **kwasync)
django.db.utils.OperationalError: connection to server at "localhost" (127.0.0.1), port 5432 failed: Connection refused
	Is the server running on that host and accepting TCP/IP connections?
connection to server at "localhost" (::1), port 5432 failed: Cannot assign requested address
	Is the server running on that host and accepting TCP/IP connections?

INFO 2022-10-01 12:15:05,732 file_cache is only supported with oauth2client<4.0.0
INFO 2022-10-01 12:15:05,916 Attempting refresh to obtain initial access_token
INFO 2022-10-01 12:15:05,949 Refreshing access_token
ERROR 2022-10-01 12:15:47,216 Internal Server Error: /canal_service/
Traceback (most recent call last):
  File "/usr/local/lib/python3.9/site-packages/django/db/backends/base/base.py", line 219, in ensure_connection
    self.connect()
  File "/usr/local/lib/python3.9/site-packages/django/utils/asyncio.py", line 26, in inner
    return func(*args, **kwargs)
  File "/usr/local/lib/python3.9/site-packages/django/db/backends/base/base.py", line 200, in connect
    self.connection = self.get_new_connection(conn_params)
  File "/usr/local/lib/python3.9/site-packages/django/utils/asyncio.py", line 26, in inner
    return func(*args, **kwargs)
  File "/usr/local/lib/python3.9/site-packages/django/db/backends/postgresql/base.py", line 187, in get_new_connection
    connection = Database.connect(**conn_params)
  File "/usr/local/lib/python3.9/site-packages/psycopg2/__init__.py", line 122, in connect
    conn = _connect(dsn, connection_factory=connection_factory, **kwasync)
psycopg2.OperationalError: could not translate host name "postgres" to address: Temporary failure in name resolution


The above exception was the direct cause of the following exception:

Traceback (most recent call last):
  File "/usr/local/lib/python3.9/site-packages/django/core/handlers/exception.py", line 47, in inner
    response = get_response(request)
  File "/usr/local/lib/python3.9/site-packages/django/core/handlers/base.py", line 181, in _get_response
    response = wrapped_callback(request, *callback_args, **callback_kwargs)
  File "/usr/local/lib/python3.9/site-packages/django/views/generic/base.py", line 70, in view
    return self.dispatch(request, *args, **kwargs)
  File "/usr/local/lib/python3.9/site-packages/django/views/generic/base.py", line 98, in dispatch
    return handler(request, *args, **kwargs)
  File "/usr/local/lib/python3.9/site-packages/django/views/generic/list.py", line 157, in get
    context = self.get_context_data()
  File "/code/table_app/views.py", line 23, in get_context_data
    ResultTable.objects.all().delete()
  File "/usr/local/lib/python3.9/site-packages/django/db/models/query.py", line 746, in delete
    deleted, _rows_count = collector.delete()
  File "/usr/local/lib/python3.9/site-packages/django/db/models/deletion.py", line 400, in delete
    with transaction.atomic(using=self.using, savepoint=False):
  File "/usr/local/lib/python3.9/site-packages/django/db/transaction.py", line 189, in __enter__
    if not connection.get_autocommit():
  File "/usr/local/lib/python3.9/site-packages/django/db/backends/base/base.py", line 389, in get_autocommit
    self.ensure_connection()
  File "/usr/local/lib/python3.9/site-packages/django/utils/asyncio.py", line 26, in inner
    return func(*args, **kwargs)
  File "/usr/local/lib/python3.9/site-packages/django/db/backends/base/base.py", line 219, in ensure_connection
    self.connect()
  File "/usr/local/lib/python3.9/site-packages/django/db/utils.py", line 90, in __exit__
    raise dj_exc_value.with_traceback(traceback) from exc_value
  File "/usr/local/lib/python3.9/site-packages/django/db/backends/base/base.py", line 219, in ensure_connection
    self.connect()
  File "/usr/local/lib/python3.9/site-packages/django/utils/asyncio.py", line 26, in inner
    return func(*args, **kwargs)
  File "/usr/local/lib/python3.9/site-packages/django/db/backends/base/base.py", line 200, in connect
    self.connection = self.get_new_connection(conn_params)
  File "/usr/local/lib/python3.9/site-packages/django/utils/asyncio.py", line 26, in inner
    return func(*args, **kwargs)
  File "/usr/local/lib/python3.9/site-packages/django/db/backends/postgresql/base.py", line 187, in get_new_connection
    connection = Database.connect(**conn_params)
  File "/usr/local/lib/python3.9/site-packages/psycopg2/__init__.py", line 122, in connect
    conn = _connect(dsn, connection_factory=connection_factory, **kwasync)
django.db.utils.OperationalError: could not translate host name "postgres" to address: Temporary failure in name resolution

INFO 2022-10-01 12:33:32,732 file_cache is only supported with oauth2client<4.0.0
INFO 2022-10-01 12:33:32,913 Attempting refresh to obtain initial access_token
INFO 2022-10-01 12:33:32,947 Refreshing access_token
ERROR 2022-10-01 12:33:34,379 Internal Server Error: /canal_service/
Traceback (most recent call last):
  File "/usr/local/lib/python3.9/site-packages/django/db/backends/base/base.py", line 219, in ensure_connection
    self.connect()
  File "/usr/local/lib/python3.9/site-packages/django/utils/asyncio.py", line 26, in inner
    return func(*args, **kwargs)
  File "/usr/local/lib/python3.9/site-packages/django/db/backends/base/base.py", line 200, in connect
    self.connection = self.get_new_connection(conn_params)
  File "/usr/local/lib/python3.9/site-packages/django/utils/asyncio.py", line 26, in inner
    return func(*args, **kwargs)
  File "/usr/local/lib/python3.9/site-packages/django/db/backends/postgresql/base.py", line 187, in get_new_connection
    connection = Database.connect(**conn_params)
  File "/usr/local/lib/python3.9/site-packages/psycopg2/__init__.py", line 122, in connect
    conn = _connect(dsn, connection_factory=connection_factory, **kwasync)
psycopg2.OperationalError: connection to server at "localhost" (127.0.0.1), port 5432 failed: Connection refused
	Is the server running on that host and accepting TCP/IP connections?
connection to server at "localhost" (::1), port 5432 failed: Cannot assign requested address
	Is the server running on that host and accepting TCP/IP connections?


The above exception was the direct cause of the following exception:

Traceback (most recent call last):
  File "/usr/local/lib/python3.9/site-packages/django/core/handlers/exception.py", line 47, in inner
    response = get_response(request)
  File "/usr/local/lib/python3.9/site-packages/django/core/handlers/base.py", line 181, in _get_response
    response = wrapped_callback(request, *callback_args, **callback_kwargs)
  File "/usr/local/lib/python3.9/site-packages/django/views/generic/base.py", line 70, in view
    return self.dispatch(request, *args, **kwargs)
  File "/usr/local/lib/python3.9/site-packages/django/views/generic/base.py", line 98, in dispatch
    return handler(request, *args, **kwargs)
  File "/usr/local/lib/python3.9/site-packages/django/views/generic/list.py", line 157, in get
    context = self.get_context_data()
  File "/code/table_app/views.py", line 23, in get_context_data
    ResultTable.objects.all().delete()
  File "/usr/local/lib/python3.9/site-packages/django/db/models/query.py", line 746, in delete
    deleted, _rows_count = collector.delete()
  File "/usr/local/lib/python3.9/site-packages/django/db/models/deletion.py", line 400, in delete
    with transaction.atomic(using=self.using, savepoint=False):
  File "/usr/local/lib/python3.9/site-packages/django/db/transaction.py", line 189, in __enter__
    if not connection.get_autocommit():
  File "/usr/local/lib/python3.9/site-packages/django/db/backends/base/base.py", line 389, in get_autocommit
    self.ensure_connection()
  File "/usr/local/lib/python3.9/site-packages/django/utils/asyncio.py", line 26, in inner
    return func(*args, **kwargs)
  File "/usr/local/lib/python3.9/site-packages/django/db/backends/base/base.py", line 219, in ensure_connection
    self.connect()
  File "/usr/local/lib/python3.9/site-packages/django/db/utils.py", line 90, in __exit__
    raise dj_exc_value.with_traceback(traceback) from exc_value
  File "/usr/local/lib/python3.9/site-packages/django/db/backends/base/base.py", line 219, in ensure_connection
    self.connect()
  File "/usr/local/lib/python3.9/site-packages/django/utils/asyncio.py", line 26, in inner
    return func(*args, **kwargs)
  File "/usr/local/lib/python3.9/site-packages/django/db/backends/base/base.py", line 200, in connect
    self.connection = self.get_new_connection(conn_params)
  File "/usr/local/lib/python3.9/site-packages/django/utils/asyncio.py", line 26, in inner
    return func(*args, **kwargs)
  File "/usr/local/lib/python3.9/site-packages/django/db/backends/postgresql/base.py", line 187, in get_new_connection
    connection = Database.connect(**conn_params)
  File "/usr/local/lib/python3.9/site-packages/psycopg2/__init__.py", line 122, in connect
    conn = _connect(dsn, connection_factory=connection_factory, **kwasync)
django.db.utils.OperationalError: connection to server at "localhost" (127.0.0.1), port 5432 failed: Connection refused
	Is the server running on that host and accepting TCP/IP connections?
connection to server at "localhost" (::1), port 5432 failed: Cannot assign requested address
	Is the server running on that host and accepting TCP/IP connections?

WARNING 2022-10-01 13:20:09,219 Not Found: /favicon.ico
INFO 2022-10-01 13:31:33,561 file_cache is only supported with oauth2client<4.0.0
INFO 2022-10-01 13:31:33,794 Attempting refresh to obtain initial access_token
INFO 2022-10-01 13:31:33,828 Refreshing access_token
ERROR 2022-10-01 13:31:35,687 Internal Server Error: /canal_service/
Traceback (most recent call last):
  File "/usr/local/lib/python3.9/site-packages/django/db/backends/base/base.py", line 219, in ensure_connection
    self.connect()
  File "/usr/local/lib/python3.9/site-packages/django/utils/asyncio.py", line 26, in inner
    return func(*args, **kwargs)
  File "/usr/local/lib/python3.9/site-packages/django/db/backends/base/base.py", line 200, in connect
    self.connection = self.get_new_connection(conn_params)
  File "/usr/local/lib/python3.9/site-packages/django/utils/asyncio.py", line 26, in inner
    return func(*args, **kwargs)
  File "/usr/local/lib/python3.9/site-packages/django/db/backends/postgresql/base.py", line 187, in get_new_connection
    connection = Database.connect(**conn_params)
  File "/usr/local/lib/python3.9/site-packages/psycopg2/__init__.py", line 122, in connect
    conn = _connect(dsn, connection_factory=connection_factory, **kwasync)
psycopg2.OperationalError: connection to server at "localhost" (127.0.0.1), port 5432 failed: Connection refused
	Is the server running on that host and accepting TCP/IP connections?
connection to server at "localhost" (::1), port 5432 failed: Cannot assign requested address
	Is the server running on that host and accepting TCP/IP connections?


The above exception was the direct cause of the following exception:

Traceback (most recent call last):
  File "/usr/local/lib/python3.9/site-packages/django/core/handlers/exception.py", line 47, in inner
    response = get_response(request)
  File "/usr/local/lib/python3.9/site-packages/django/core/handlers/base.py", line 181, in _get_response
    response = wrapped_callback(request, *callback_args, **callback_kwargs)
  File "/usr/local/lib/python3.9/site-packages/django/views/generic/base.py", line 70, in view
    return self.dispatch(request, *args, **kwargs)
  File "/usr/local/lib/python3.9/site-packages/django/views/generic/base.py", line 98, in dispatch
    return handler(request, *args, **kwargs)
  File "/usr/local/lib/python3.9/site-packages/django/views/generic/list.py", line 157, in get
    context = self.get_context_data()
  File "/code/table_app/views.py", line 23, in get_context_data
    ResultTable.objects.all().delete()
  File "/usr/local/lib/python3.9/site-packages/django/db/models/query.py", line 746, in delete
    deleted, _rows_count = collector.delete()
  File "/usr/local/lib/python3.9/site-packages/django/db/models/deletion.py", line 400, in delete
    with transaction.atomic(using=self.using, savepoint=False):
  File "/usr/local/lib/python3.9/site-packages/django/db/transaction.py", line 189, in __enter__
    if not connection.get_autocommit():
  File "/usr/local/lib/python3.9/site-packages/django/db/backends/base/base.py", line 389, in get_autocommit
    self.ensure_connection()
  File "/usr/local/lib/python3.9/site-packages/django/utils/asyncio.py", line 26, in inner
    return func(*args, **kwargs)
  File "/usr/local/lib/python3.9/site-packages/django/db/backends/base/base.py", line 219, in ensure_connection
    self.connect()
  File "/usr/local/lib/python3.9/site-packages/django/db/utils.py", line 90, in __exit__
    raise dj_exc_value.with_traceback(traceback) from exc_value
  File "/usr/local/lib/python3.9/site-packages/django/db/backends/base/base.py", line 219, in ensure_connection
    self.connect()
  File "/usr/local/lib/python3.9/site-packages/django/utils/asyncio.py", line 26, in inner
    return func(*args, **kwargs)
  File "/usr/local/lib/python3.9/site-packages/django/db/backends/base/base.py", line 200, in connect
    self.connection = self.get_new_connection(conn_params)
  File "/usr/local/lib/python3.9/site-packages/django/utils/asyncio.py", line 26, in inner
    return func(*args, **kwargs)
  File "/usr/local/lib/python3.9/site-packages/django/db/backends/postgresql/base.py", line 187, in get_new_connection
    connection = Database.connect(**conn_params)
  File "/usr/local/lib/python3.9/site-packages/psycopg2/__init__.py", line 122, in connect
    conn = _connect(dsn, connection_factory=connection_factory, **kwasync)
django.db.utils.OperationalError: connection to server at "localhost" (127.0.0.1), port 5432 failed: Connection refused
	Is the server running on that host and accepting TCP/IP connections?
connection to server at "localhost" (::1), port 5432 failed: Cannot assign requested address
	Is the server running on that host and accepting TCP/IP connections?

INFO 2022-10-01 13:37:00,237 file_cache is only supported with oauth2client<4.0.0
INFO 2022-10-01 13:37:00,431 Attempting refresh to obtain initial access_token
INFO 2022-10-01 13:37:00,464 Refreshing access_token
INFO 2022-10-01 13:37:32,265 file_cache is only supported with oauth2client<4.0.0
INFO 2022-10-01 13:37:32,473 Attempting refresh to obtain initial access_token
INFO 2022-10-01 13:37:32,508 Refreshing access_token
INFO 2022-10-01 13:38:10,614 file_cache is only supported with oauth2client<4.0.0
INFO 2022-10-01 13:38:10,781 Attempting refresh to obtain initial access_token
INFO 2022-10-01 13:38:10,814 Refreshing access_token
INFO 2022-10-01 13:38:41,373 file_cache is only supported with oauth2client<4.0.0
INFO 2022-10-01 13:38:41,601 Attempting refresh to obtain initial access_token
INFO 2022-10-01 13:38:41,642 Refreshing access_token
INFO 2022-10-01 13:39:19,097 file_cache is only supported with oauth2client<4.0.0
INFO 2022-10-01 13:39:19,296 Attempting refresh to obtain initial access_token
INFO 2022-10-01 13:39:19,337 Refreshing access_token
INFO 2022-10-01 13:40:45,412 file_cache is only supported with oauth2client<4.0.0
INFO 2022-10-01 13:40:45,589 Attempting refresh to obtain initial access_token
INFO 2022-10-01 13:40:45,622 Refreshing access_token
ERROR 2022-10-01 13:40:46,704 Internal Server Error: /canal_service/
Traceback (most recent call last):
  File "/usr/local/lib/python3.9/site-packages/django/db/backends/base/base.py", line 219, in ensure_connection
    self.connect()
  File "/usr/local/lib/python3.9/site-packages/django/utils/asyncio.py", line 26, in inner
    return func(*args, **kwargs)
  File "/usr/local/lib/python3.9/site-packages/django/db/backends/base/base.py", line 200, in connect
    self.connection = self.get_new_connection(conn_params)
  File "/usr/local/lib/python3.9/site-packages/django/utils/asyncio.py", line 26, in inner
    return func(*args, **kwargs)
  File "/usr/local/lib/python3.9/site-packages/django/db/backends/postgresql/base.py", line 187, in get_new_connection
    connection = Database.connect(**conn_params)
  File "/usr/local/lib/python3.9/site-packages/psycopg2/__init__.py", line 122, in connect
    conn = _connect(dsn, connection_factory=connection_factory, **kwasync)
psycopg2.OperationalError: connection to server at "0.0.0.0", port 5432 failed: Connection refused
	Is the server running on that host and accepting TCP/IP connections?


The above exception was the direct cause of the following exception:

Traceback (most recent call last):
  File "/usr/local/lib/python3.9/site-packages/django/core/handlers/exception.py", line 47, in inner
    response = get_response(request)
  File "/usr/local/lib/python3.9/site-packages/django/core/handlers/base.py", line 181, in _get_response
    response = wrapped_callback(request, *callback_args, **callback_kwargs)
  File "/usr/local/lib/python3.9/site-packages/django/views/generic/base.py", line 70, in view
    return self.dispatch(request, *args, **kwargs)
  File "/usr/local/lib/python3.9/site-packages/django/views/generic/base.py", line 98, in dispatch
    return handler(request, *args, **kwargs)
  File "/usr/local/lib/python3.9/site-packages/django/views/generic/list.py", line 157, in get
    context = self.get_context_data()
  File "/code/table_app/views.py", line 23, in get_context_data
    ResultTable.objects.all().delete()
  File "/usr/local/lib/python3.9/site-packages/django/db/models/query.py", line 746, in delete
    deleted, _rows_count = collector.delete()
  File "/usr/local/lib/python3.9/site-packages/django/db/models/deletion.py", line 400, in delete
    with transaction.atomic(using=self.using, savepoint=False):
  File "/usr/local/lib/python3.9/site-packages/django/db/transaction.py", line 189, in __enter__
    if not connection.get_autocommit():
  File "/usr/local/lib/python3.9/site-packages/django/db/backends/base/base.py", line 389, in get_autocommit
    self.ensure_connection()
  File "/usr/local/lib/python3.9/site-packages/django/utils/asyncio.py", line 26, in inner
    return func(*args, **kwargs)
  File "/usr/local/lib/python3.9/site-packages/django/db/backends/base/base.py", line 219, in ensure_connection
    self.connect()
  File "/usr/local/lib/python3.9/site-packages/django/db/utils.py", line 90, in __exit__
    raise dj_exc_value.with_traceback(traceback) from exc_value
  File "/usr/local/lib/python3.9/site-packages/django/db/backends/base/base.py", line 219, in ensure_connection
    self.connect()
  File "/usr/local/lib/python3.9/site-packages/django/utils/asyncio.py", line 26, in inner
    return func(*args, **kwargs)
  File "/usr/local/lib/python3.9/site-packages/django/db/backends/base/base.py", line 200, in connect
    self.connection = self.get_new_connection(conn_params)
  File "/usr/local/lib/python3.9/site-packages/django/utils/asyncio.py", line 26, in inner
    return func(*args, **kwargs)
  File "/usr/local/lib/python3.9/site-packages/django/db/backends/postgresql/base.py", line 187, in get_new_connection
    connection = Database.connect(**conn_params)
  File "/usr/local/lib/python3.9/site-packages/psycopg2/__init__.py", line 122, in connect
    conn = _connect(dsn, connection_factory=connection_factory, **kwasync)
django.db.utils.OperationalError: connection to server at "0.0.0.0", port 5432 failed: Connection refused
	Is the server running on that host and accepting TCP/IP connections?

INFO 2022-10-01 13:42:52,620 file_cache is only supported with oauth2client<4.0.0
INFO 2022-10-01 13:42:52,825 Attempting refresh to obtain initial access_token
INFO 2022-10-01 13:42:52,859 Refreshing access_token
ERROR 2022-10-01 13:42:54,080 Internal Server Error: /canal_service/
Traceback (most recent call last):
  File "/usr/local/lib/python3.9/site-packages/django/db/backends/base/base.py", line 219, in ensure_connection
    self.connect()
  File "/usr/local/lib/python3.9/site-packages/django/utils/asyncio.py", line 26, in inner
    return func(*args, **kwargs)
  File "/usr/local/lib/python3.9/site-packages/django/db/backends/base/base.py", line 200, in connect
    self.connection = self.get_new_connection(conn_params)
  File "/usr/local/lib/python3.9/site-packages/django/utils/asyncio.py", line 26, in inner
    return func(*args, **kwargs)
  File "/usr/local/lib/python3.9/site-packages/django/db/backends/postgresql/base.py", line 187, in get_new_connection
    connection = Database.connect(**conn_params)
  File "/usr/local/lib/python3.9/site-packages/psycopg2/__init__.py", line 122, in connect
    conn = _connect(dsn, connection_factory=connection_factory, **kwasync)
psycopg2.OperationalError: connection to server at "0.0.0.0", port 5432 failed: Connection refused
	Is the server running on that host and accepting TCP/IP connections?


The above exception was the direct cause of the following exception:

Traceback (most recent call last):
  File "/usr/local/lib/python3.9/site-packages/django/core/handlers/exception.py", line 47, in inner
    response = get_response(request)
  File "/usr/local/lib/python3.9/site-packages/django/core/handlers/base.py", line 181, in _get_response
    response = wrapped_callback(request, *callback_args, **callback_kwargs)
  File "/usr/local/lib/python3.9/site-packages/django/views/generic/base.py", line 70, in view
    return self.dispatch(request, *args, **kwargs)
  File "/usr/local/lib/python3.9/site-packages/django/views/generic/base.py", line 98, in dispatch
    return handler(request, *args, **kwargs)
  File "/usr/local/lib/python3.9/site-packages/django/views/generic/list.py", line 157, in get
    context = self.get_context_data()
  File "/code/table_app/views.py", line 23, in get_context_data
    ResultTable.objects.all().delete()
  File "/usr/local/lib/python3.9/site-packages/django/db/models/query.py", line 746, in delete
    deleted, _rows_count = collector.delete()
  File "/usr/local/lib/python3.9/site-packages/django/db/models/deletion.py", line 400, in delete
    with transaction.atomic(using=self.using, savepoint=False):
  File "/usr/local/lib/python3.9/site-packages/django/db/transaction.py", line 189, in __enter__
    if not connection.get_autocommit():
  File "/usr/local/lib/python3.9/site-packages/django/db/backends/base/base.py", line 389, in get_autocommit
    self.ensure_connection()
  File "/usr/local/lib/python3.9/site-packages/django/utils/asyncio.py", line 26, in inner
    return func(*args, **kwargs)
  File "/usr/local/lib/python3.9/site-packages/django/db/backends/base/base.py", line 219, in ensure_connection
    self.connect()
  File "/usr/local/lib/python3.9/site-packages/django/db/utils.py", line 90, in __exit__
    raise dj_exc_value.with_traceback(traceback) from exc_value
  File "/usr/local/lib/python3.9/site-packages/django/db/backends/base/base.py", line 219, in ensure_connection
    self.connect()
  File "/usr/local/lib/python3.9/site-packages/django/utils/asyncio.py", line 26, in inner
    return func(*args, **kwargs)
  File "/usr/local/lib/python3.9/site-packages/django/db/backends/base/base.py", line 200, in connect
    self.connection = self.get_new_connection(conn_params)
  File "/usr/local/lib/python3.9/site-packages/django/utils/asyncio.py", line 26, in inner
    return func(*args, **kwargs)
  File "/usr/local/lib/python3.9/site-packages/django/db/backends/postgresql/base.py", line 187, in get_new_connection
    connection = Database.connect(**conn_params)
  File "/usr/local/lib/python3.9/site-packages/psycopg2/__init__.py", line 122, in connect
    conn = _connect(dsn, connection_factory=connection_factory, **kwasync)
django.db.utils.OperationalError: connection to server at "0.0.0.0", port 5432 failed: Connection refused
	Is the server running on that host and accepting TCP/IP connections?

INFO 2022-10-01 14:15:27,516 file_cache is only supported with oauth2client<4.0.0
INFO 2022-10-01 14:15:27,714 Attempting refresh to obtain initial access_token
INFO 2022-10-01 14:15:27,753 Refreshing access_token
INFO 2022-10-01 14:17:33,400 file_cache is only supported with oauth2client<4.0.0
INFO 2022-10-01 14:17:33,566 Attempting refresh to obtain initial access_token
INFO 2022-10-01 14:17:33,599 Refreshing access_token
ERROR 2022-10-01 14:17:34,852 Internal Server Error: /canal_service/
Traceback (most recent call last):
  File "/usr/local/lib/python3.9/site-packages/django/db/backends/base/base.py", line 219, in ensure_connection
    self.connect()
  File "/usr/local/lib/python3.9/site-packages/django/utils/asyncio.py", line 26, in inner
    return func(*args, **kwargs)
  File "/usr/local/lib/python3.9/site-packages/django/db/backends/base/base.py", line 200, in connect
    self.connection = self.get_new_connection(conn_params)
  File "/usr/local/lib/python3.9/site-packages/django/utils/asyncio.py", line 26, in inner
    return func(*args, **kwargs)
  File "/usr/local/lib/python3.9/site-packages/django/db/backends/postgresql/base.py", line 187, in get_new_connection
    connection = Database.connect(**conn_params)
  File "/usr/local/lib/python3.9/site-packages/psycopg2/__init__.py", line 122, in connect
    conn = _connect(dsn, connection_factory=connection_factory, **kwasync)
psycopg2.OperationalError: connection to server at "localhost" (127.0.0.1), port 5432 failed: Connection refused
	Is the server running on that host and accepting TCP/IP connections?
connection to server at "localhost" (::1), port 5432 failed: Cannot assign requested address
	Is the server running on that host and accepting TCP/IP connections?


The above exception was the direct cause of the following exception:

Traceback (most recent call last):
  File "/usr/local/lib/python3.9/site-packages/django/core/handlers/exception.py", line 47, in inner
    response = get_response(request)
  File "/usr/local/lib/python3.9/site-packages/django/core/handlers/base.py", line 181, in _get_response
    response = wrapped_callback(request, *callback_args, **callback_kwargs)
  File "/usr/local/lib/python3.9/site-packages/django/views/generic/base.py", line 70, in view
    return self.dispatch(request, *args, **kwargs)
  File "/usr/local/lib/python3.9/site-packages/django/views/generic/base.py", line 98, in dispatch
    return handler(request, *args, **kwargs)
  File "/usr/local/lib/python3.9/site-packages/django/views/generic/list.py", line 157, in get
    context = self.get_context_data()
  File "/code/table_app/views.py", line 23, in get_context_data
    ResultTable.objects.all().delete()
  File "/usr/local/lib/python3.9/site-packages/django/db/models/query.py", line 746, in delete
    deleted, _rows_count = collector.delete()
  File "/usr/local/lib/python3.9/site-packages/django/db/models/deletion.py", line 400, in delete
    with transaction.atomic(using=self.using, savepoint=False):
  File "/usr/local/lib/python3.9/site-packages/django/db/transaction.py", line 189, in __enter__
    if not connection.get_autocommit():
  File "/usr/local/lib/python3.9/site-packages/django/db/backends/base/base.py", line 389, in get_autocommit
    self.ensure_connection()
  File "/usr/local/lib/python3.9/site-packages/django/utils/asyncio.py", line 26, in inner
    return func(*args, **kwargs)
  File "/usr/local/lib/python3.9/site-packages/django/db/backends/base/base.py", line 219, in ensure_connection
    self.connect()
  File "/usr/local/lib/python3.9/site-packages/django/db/utils.py", line 90, in __exit__
    raise dj_exc_value.with_traceback(traceback) from exc_value
  File "/usr/local/lib/python3.9/site-packages/django/db/backends/base/base.py", line 219, in ensure_connection
    self.connect()
  File "/usr/local/lib/python3.9/site-packages/django/utils/asyncio.py", line 26, in inner
    return func(*args, **kwargs)
  File "/usr/local/lib/python3.9/site-packages/django/db/backends/base/base.py", line 200, in connect
    self.connection = self.get_new_connection(conn_params)
  File "/usr/local/lib/python3.9/site-packages/django/utils/asyncio.py", line 26, in inner
    return func(*args, **kwargs)
  File "/usr/local/lib/python3.9/site-packages/django/db/backends/postgresql/base.py", line 187, in get_new_connection
    connection = Database.connect(**conn_params)
  File "/usr/local/lib/python3.9/site-packages/psycopg2/__init__.py", line 122, in connect
    conn = _connect(dsn, connection_factory=connection_factory, **kwasync)
django.db.utils.OperationalError: connection to server at "localhost" (127.0.0.1), port 5432 failed: Connection refused
	Is the server running on that host and accepting TCP/IP connections?
connection to server at "localhost" (::1), port 5432 failed: Cannot assign requested address
	Is the server running on that host and accepting TCP/IP connections?

WARNING 2022-10-01 14:17:35,294 Not Found: /favicon.ico
INFO 2022-10-01 14:20:57,114 Watching for file changes with StatReloader
INFO 2022-10-01 14:27:18,697 /code/КаналсервисTest/settings.py changed, reloading.
INFO 2022-10-01 14:27:20,094 Watching for file changes with StatReloader
INFO 2022-10-01 14:41:07,150 Watching for file changes with StatReloader
INFO 2022-10-01 14:43:14,819 Watching for file changes with StatReloader
INFO 2022-10-01 14:45:20,651 file_cache is only supported with oauth2client<4.0.0
INFO 2022-10-01 14:45:20,824 Attempting refresh to obtain initial access_token
INFO 2022-10-01 14:45:20,857 Refreshing access_token
ERROR 2022-10-01 14:45:22,511 Internal Server Error: /canal_service/
Traceback (most recent call last):
  File "/usr/local/lib/python3.9/site-packages/django/db/backends/base/base.py", line 219, in ensure_connection
    self.connect()
  File "/usr/local/lib/python3.9/site-packages/django/utils/asyncio.py", line 26, in inner
    return func(*args, **kwargs)
  File "/usr/local/lib/python3.9/site-packages/django/db/backends/base/base.py", line 200, in connect
    self.connection = self.get_new_connection(conn_params)
  File "/usr/local/lib/python3.9/site-packages/django/utils/asyncio.py", line 26, in inner
    return func(*args, **kwargs)
  File "/usr/local/lib/python3.9/site-packages/django/db/backends/postgresql/base.py", line 187, in get_new_connection
    connection = Database.connect(**conn_params)
  File "/usr/local/lib/python3.9/site-packages/psycopg2/__init__.py", line 122, in connect
    conn = _connect(dsn, connection_factory=connection_factory, **kwasync)
psycopg2.OperationalError: connection to server at "localhost" (127.0.0.1), port 5432 failed: Connection refused
	Is the server running on that host and accepting TCP/IP connections?
connection to server at "localhost" (::1), port 5432 failed: Cannot assign requested address
	Is the server running on that host and accepting TCP/IP connections?


The above exception was the direct cause of the following exception:

Traceback (most recent call last):
  File "/usr/local/lib/python3.9/site-packages/django/core/handlers/exception.py", line 47, in inner
    response = get_response(request)
  File "/usr/local/lib/python3.9/site-packages/django/core/handlers/base.py", line 181, in _get_response
    response = wrapped_callback(request, *callback_args, **callback_kwargs)
  File "/usr/local/lib/python3.9/site-packages/django/views/generic/base.py", line 70, in view
    return self.dispatch(request, *args, **kwargs)
  File "/usr/local/lib/python3.9/site-packages/django/views/generic/base.py", line 98, in dispatch
    return handler(request, *args, **kwargs)
  File "/usr/local/lib/python3.9/site-packages/django/views/generic/list.py", line 157, in get
    context = self.get_context_data()
  File "/code/table_app/views.py", line 23, in get_context_data
    ResultTable.objects.all().delete()
  File "/usr/local/lib/python3.9/site-packages/django/db/models/query.py", line 746, in delete
    deleted, _rows_count = collector.delete()
  File "/usr/local/lib/python3.9/site-packages/django/db/models/deletion.py", line 400, in delete
    with transaction.atomic(using=self.using, savepoint=False):
  File "/usr/local/lib/python3.9/site-packages/django/db/transaction.py", line 189, in __enter__
    if not connection.get_autocommit():
  File "/usr/local/lib/python3.9/site-packages/django/db/backends/base/base.py", line 389, in get_autocommit
    self.ensure_connection()
  File "/usr/local/lib/python3.9/site-packages/django/utils/asyncio.py", line 26, in inner
    return func(*args, **kwargs)
  File "/usr/local/lib/python3.9/site-packages/django/db/backends/base/base.py", line 219, in ensure_connection
    self.connect()
  File "/usr/local/lib/python3.9/site-packages/django/db/utils.py", line 90, in __exit__
    raise dj_exc_value.with_traceback(traceback) from exc_value
  File "/usr/local/lib/python3.9/site-packages/django/db/backends/base/base.py", line 219, in ensure_connection
    self.connect()
  File "/usr/local/lib/python3.9/site-packages/django/utils/asyncio.py", line 26, in inner
    return func(*args, **kwargs)
  File "/usr/local/lib/python3.9/site-packages/django/db/backends/base/base.py", line 200, in connect
    self.connection = self.get_new_connection(conn_params)
  File "/usr/local/lib/python3.9/site-packages/django/utils/asyncio.py", line 26, in inner
    return func(*args, **kwargs)
  File "/usr/local/lib/python3.9/site-packages/django/db/backends/postgresql/base.py", line 187, in get_new_connection
    connection = Database.connect(**conn_params)
  File "/usr/local/lib/python3.9/site-packages/psycopg2/__init__.py", line 122, in connect
    conn = _connect(dsn, connection_factory=connection_factory, **kwasync)
django.db.utils.OperationalError: connection to server at "localhost" (127.0.0.1), port 5432 failed: Connection refused
	Is the server running on that host and accepting TCP/IP connections?
connection to server at "localhost" (::1), port 5432 failed: Cannot assign requested address
	Is the server running on that host and accepting TCP/IP connections?

INFO 2022-10-01 17:48:40,862 Watching for file changes with StatReloader
INFO 2022-10-01 17:48:52,268 file_cache is only supported with oauth2client<4.0.0
INFO 2022-10-01 17:48:52,473 Attempting refresh to obtain initial access_token
INFO 2022-10-01 17:48:52,507 Refreshing access_token
WARNING 2022-10-01 17:48:54,174 Not Found: /static/css/base.css
WARNING 2022-10-01 17:48:54,291 Not Found: /static/images/logo_canal.png
WARNING 2022-10-01 17:48:54,351 Not Found: /static/css/base.css
WARNING 2022-10-01 17:48:54,943 Not Found: /static/images/favicon.ico
INFO 2022-10-01 14:49:13,380 file_cache is only supported with oauth2client<4.0.0
INFO 2022-10-01 14:49:13,550 Attempting refresh to obtain initial access_token
INFO 2022-10-01 14:49:13,587 Refreshing access_token
ERROR 2022-10-01 14:49:14,547 Internal Server Error: /canal_service/
Traceback (most recent call last):
  File "/usr/local/lib/python3.9/site-packages/django/db/backends/base/base.py", line 219, in ensure_connection
    self.connect()
  File "/usr/local/lib/python3.9/site-packages/django/utils/asyncio.py", line 26, in inner
    return func(*args, **kwargs)
  File "/usr/local/lib/python3.9/site-packages/django/db/backends/base/base.py", line 200, in connect
    self.connection = self.get_new_connection(conn_params)
  File "/usr/local/lib/python3.9/site-packages/django/utils/asyncio.py", line 26, in inner
    return func(*args, **kwargs)
  File "/usr/local/lib/python3.9/site-packages/django/db/backends/postgresql/base.py", line 187, in get_new_connection
    connection = Database.connect(**conn_params)
  File "/usr/local/lib/python3.9/site-packages/psycopg2/__init__.py", line 122, in connect
    conn = _connect(dsn, connection_factory=connection_factory, **kwasync)
psycopg2.OperationalError: connection to server at "localhost" (127.0.0.1), port 5432 failed: Connection refused
	Is the server running on that host and accepting TCP/IP connections?
connection to server at "localhost" (::1), port 5432 failed: Cannot assign requested address
	Is the server running on that host and accepting TCP/IP connections?


The above exception was the direct cause of the following exception:

Traceback (most recent call last):
  File "/usr/local/lib/python3.9/site-packages/django/core/handlers/exception.py", line 47, in inner
    response = get_response(request)
  File "/usr/local/lib/python3.9/site-packages/django/core/handlers/base.py", line 181, in _get_response
    response = wrapped_callback(request, *callback_args, **callback_kwargs)
  File "/usr/local/lib/python3.9/site-packages/django/views/generic/base.py", line 70, in view
    return self.dispatch(request, *args, **kwargs)
  File "/usr/local/lib/python3.9/site-packages/django/views/generic/base.py", line 98, in dispatch
    return handler(request, *args, **kwargs)
  File "/usr/local/lib/python3.9/site-packages/django/views/generic/list.py", line 157, in get
    context = self.get_context_data()
  File "/code/table_app/views.py", line 23, in get_context_data
    ResultTable.objects.all().delete()
  File "/usr/local/lib/python3.9/site-packages/django/db/models/query.py", line 746, in delete
    deleted, _rows_count = collector.delete()
  File "/usr/local/lib/python3.9/site-packages/django/db/models/deletion.py", line 400, in delete
    with transaction.atomic(using=self.using, savepoint=False):
  File "/usr/local/lib/python3.9/site-packages/django/db/transaction.py", line 189, in __enter__
    if not connection.get_autocommit():
  File "/usr/local/lib/python3.9/site-packages/django/db/backends/base/base.py", line 389, in get_autocommit
    self.ensure_connection()
  File "/usr/local/lib/python3.9/site-packages/django/utils/asyncio.py", line 26, in inner
    return func(*args, **kwargs)
  File "/usr/local/lib/python3.9/site-packages/django/db/backends/base/base.py", line 219, in ensure_connection
    self.connect()
  File "/usr/local/lib/python3.9/site-packages/django/db/utils.py", line 90, in __exit__
    raise dj_exc_value.with_traceback(traceback) from exc_value
  File "/usr/local/lib/python3.9/site-packages/django/db/backends/base/base.py", line 219, in ensure_connection
    self.connect()
  File "/usr/local/lib/python3.9/site-packages/django/utils/asyncio.py", line 26, in inner
    return func(*args, **kwargs)
  File "/usr/local/lib/python3.9/site-packages/django/db/backends/base/base.py", line 200, in connect
    self.connection = self.get_new_connection(conn_params)
  File "/usr/local/lib/python3.9/site-packages/django/utils/asyncio.py", line 26, in inner
    return func(*args, **kwargs)
  File "/usr/local/lib/python3.9/site-packages/django/db/backends/postgresql/base.py", line 187, in get_new_connection
    connection = Database.connect(**conn_params)
  File "/usr/local/lib/python3.9/site-packages/psycopg2/__init__.py", line 122, in connect
    conn = _connect(dsn, connection_factory=connection_factory, **kwasync)
django.db.utils.OperationalError: connection to server at "localhost" (127.0.0.1), port 5432 failed: Connection refused
	Is the server running on that host and accepting TCP/IP connections?
connection to server at "localhost" (::1), port 5432 failed: Cannot assign requested address
	Is the server running on that host and accepting TCP/IP connections?

INFO 2022-10-01 14:50:22,712 file_cache is only supported with oauth2client<4.0.0
INFO 2022-10-01 14:50:22,931 Attempting refresh to obtain initial access_token
INFO 2022-10-01 14:50:22,969 Refreshing access_token
ERROR 2022-10-01 14:50:23,987 Internal Server Error: /canal_service/
Traceback (most recent call last):
  File "/usr/local/lib/python3.9/site-packages/django/db/backends/base/base.py", line 219, in ensure_connection
    self.connect()
  File "/usr/local/lib/python3.9/site-packages/django/utils/asyncio.py", line 26, in inner
    return func(*args, **kwargs)
  File "/usr/local/lib/python3.9/site-packages/django/db/backends/base/base.py", line 200, in connect
    self.connection = self.get_new_connection(conn_params)
  File "/usr/local/lib/python3.9/site-packages/django/utils/asyncio.py", line 26, in inner
    return func(*args, **kwargs)
  File "/usr/local/lib/python3.9/site-packages/django/db/backends/postgresql/base.py", line 187, in get_new_connection
    connection = Database.connect(**conn_params)
  File "/usr/local/lib/python3.9/site-packages/psycopg2/__init__.py", line 122, in connect
    conn = _connect(dsn, connection_factory=connection_factory, **kwasync)
psycopg2.OperationalError: connection to server at "localhost" (127.0.0.1), port 5432 failed: Connection refused
	Is the server running on that host and accepting TCP/IP connections?
connection to server at "localhost" (::1), port 5432 failed: Cannot assign requested address
	Is the server running on that host and accepting TCP/IP connections?


The above exception was the direct cause of the following exception:

Traceback (most recent call last):
  File "/usr/local/lib/python3.9/site-packages/django/core/handlers/exception.py", line 47, in inner
    response = get_response(request)
  File "/usr/local/lib/python3.9/site-packages/django/core/handlers/base.py", line 181, in _get_response
    response = wrapped_callback(request, *callback_args, **callback_kwargs)
  File "/usr/local/lib/python3.9/site-packages/django/views/generic/base.py", line 70, in view
    return self.dispatch(request, *args, **kwargs)
  File "/usr/local/lib/python3.9/site-packages/django/views/generic/base.py", line 98, in dispatch
    return handler(request, *args, **kwargs)
  File "/usr/local/lib/python3.9/site-packages/django/views/generic/list.py", line 157, in get
    context = self.get_context_data()
  File "/code/table_app/views.py", line 23, in get_context_data
    ResultTable.objects.all().delete()
  File "/usr/local/lib/python3.9/site-packages/django/db/models/query.py", line 746, in delete
    deleted, _rows_count = collector.delete()
  File "/usr/local/lib/python3.9/site-packages/django/db/models/deletion.py", line 400, in delete
    with transaction.atomic(using=self.using, savepoint=False):
  File "/usr/local/lib/python3.9/site-packages/django/db/transaction.py", line 189, in __enter__
    if not connection.get_autocommit():
  File "/usr/local/lib/python3.9/site-packages/django/db/backends/base/base.py", line 389, in get_autocommit
    self.ensure_connection()
  File "/usr/local/lib/python3.9/site-packages/django/utils/asyncio.py", line 26, in inner
    return func(*args, **kwargs)
  File "/usr/local/lib/python3.9/site-packages/django/db/backends/base/base.py", line 219, in ensure_connection
    self.connect()
  File "/usr/local/lib/python3.9/site-packages/django/db/utils.py", line 90, in __exit__
    raise dj_exc_value.with_traceback(traceback) from exc_value
  File "/usr/local/lib/python3.9/site-packages/django/db/backends/base/base.py", line 219, in ensure_connection
    self.connect()
  File "/usr/local/lib/python3.9/site-packages/django/utils/asyncio.py", line 26, in inner
    return func(*args, **kwargs)
  File "/usr/local/lib/python3.9/site-packages/django/db/backends/base/base.py", line 200, in connect
    self.connection = self.get_new_connection(conn_params)
  File "/usr/local/lib/python3.9/site-packages/django/utils/asyncio.py", line 26, in inner
    return func(*args, **kwargs)
  File "/usr/local/lib/python3.9/site-packages/django/db/backends/postgresql/base.py", line 187, in get_new_connection
    connection = Database.connect(**conn_params)
  File "/usr/local/lib/python3.9/site-packages/psycopg2/__init__.py", line 122, in connect
    conn = _connect(dsn, connection_factory=connection_factory, **kwasync)
django.db.utils.OperationalError: connection to server at "localhost" (127.0.0.1), port 5432 failed: Connection refused
	Is the server running on that host and accepting TCP/IP connections?
connection to server at "localhost" (::1), port 5432 failed: Cannot assign requested address
	Is the server running on that host and accepting TCP/IP connections?

INFO 2022-10-01 14:55:42,627 file_cache is only supported with oauth2client<4.0.0
INFO 2022-10-01 14:55:42,852 Attempting refresh to obtain initial access_token
INFO 2022-10-01 14:55:42,889 Refreshing access_token
ERROR 2022-10-01 14:55:44,396 Internal Server Error: /canal_service/
Traceback (most recent call last):
  File "/usr/local/lib/python3.9/site-packages/django/db/backends/utils.py", line 84, in _execute
    return self.cursor.execute(sql, params)
psycopg2.errors.UndefinedTable: relation "table_app_resulttable" does not exist
LINE 1: DELETE FROM "table_app_resulttable"
                    ^


The above exception was the direct cause of the following exception:

Traceback (most recent call last):
  File "/usr/local/lib/python3.9/site-packages/django/core/handlers/exception.py", line 47, in inner
    response = get_response(request)
  File "/usr/local/lib/python3.9/site-packages/django/core/handlers/base.py", line 181, in _get_response
    response = wrapped_callback(request, *callback_args, **callback_kwargs)
  File "/usr/local/lib/python3.9/site-packages/django/views/generic/base.py", line 70, in view
    return self.dispatch(request, *args, **kwargs)
  File "/usr/local/lib/python3.9/site-packages/django/views/generic/base.py", line 98, in dispatch
    return handler(request, *args, **kwargs)
  File "/usr/local/lib/python3.9/site-packages/django/views/generic/list.py", line 157, in get
    context = self.get_context_data()
  File "/code/table_app/views.py", line 23, in get_context_data
    ResultTable.objects.all().delete()
  File "/usr/local/lib/python3.9/site-packages/django/db/models/query.py", line 746, in delete
    deleted, _rows_count = collector.delete()
  File "/usr/local/lib/python3.9/site-packages/django/db/models/deletion.py", line 410, in delete
    count = qs._raw_delete(using=self.using)
  File "/usr/local/lib/python3.9/site-packages/django/db/models/query.py", line 762, in _raw_delete
    cursor = query.get_compiler(using).execute_sql(CURSOR)
  File "/usr/local/lib/python3.9/site-packages/django/db/models/sql/compiler.py", line 1175, in execute_sql
    cursor.execute(sql, params)
  File "/usr/local/lib/python3.9/site-packages/django/db/backends/utils.py", line 98, in execute
    return super().execute(sql, params)
  File "/usr/local/lib/python3.9/site-packages/django/db/backends/utils.py", line 66, in execute
    return self._execute_with_wrappers(sql, params, many=False, executor=self._execute)
  File "/usr/local/lib/python3.9/site-packages/django/db/backends/utils.py", line 75, in _execute_with_wrappers
    return executor(sql, params, many, context)
  File "/usr/local/lib/python3.9/site-packages/django/db/backends/utils.py", line 84, in _execute
    return self.cursor.execute(sql, params)
  File "/usr/local/lib/python3.9/site-packages/django/db/utils.py", line 90, in __exit__
    raise dj_exc_value.with_traceback(traceback) from exc_value
  File "/usr/local/lib/python3.9/site-packages/django/db/backends/utils.py", line 84, in _execute
    return self.cursor.execute(sql, params)
django.db.utils.ProgrammingError: relation "table_app_resulttable" does not exist
LINE 1: DELETE FROM "table_app_resulttable"
                    ^

INFO 2022-10-01 14:56:07,928 file_cache is only supported with oauth2client<4.0.0
INFO 2022-10-01 14:56:08,069 Attempting refresh to obtain initial access_token
INFO 2022-10-01 14:56:08,103 Refreshing access_token
WARNING 2022-10-01 14:56:09,822 Not Found: /static/css/base.css
WARNING 2022-10-01 14:56:09,837 Not Found: /static/images/logo_canal.png
WARNING 2022-10-01 14:56:09,848 Not Found: /static/css/base.css
INFO 2022-10-01 14:57:48,275 file_cache is only supported with oauth2client<4.0.0
INFO 2022-10-01 14:57:48,457 Attempting refresh to obtain initial access_token
INFO 2022-10-01 14:57:48,492 Refreshing access_token
WARNING 2022-10-01 14:57:49,906 Not Found: /static/css/base.css
WARNING 2022-10-01 14:57:51,188 Not Found: /static/images/logo_canal.png
WARNING 2022-10-01 14:57:51,234 Not Found: /static/css/base.css
INFO 2022-10-01 14:59:09,538 file_cache is only supported with oauth2client<4.0.0
INFO 2022-10-01 14:59:09,710 Attempting refresh to obtain initial access_token
INFO 2022-10-01 14:59:09,744 Refreshing access_token
WARNING 2022-10-01 14:59:12,275 Not Found: /static/css/base.css
WARNING 2022-10-01 14:59:12,727 Not Found: /static/css/base.css
WARNING 2022-10-01 14:59:12,811 Not Found: /static/images/logo_canal.png
INFO 2022-10-01 15:01:27,016 file_cache is only supported with oauth2client<4.0.0
INFO 2022-10-01 15:01:27,180 Attempting refresh to obtain initial access_token
INFO 2022-10-01 15:01:27,213 Refreshing access_token
WARNING 2022-10-01 15:01:30,031 Not Found: /static/css/base.css
WARNING 2022-10-01 15:01:30,215 Not Found: /static/css/base.css
WARNING 2022-10-01 15:01:30,223 Not Found: /static/images/logo_canal.png
INFO 2022-10-01 15:04:09,397 file_cache is only supported with oauth2client<4.0.0
INFO 2022-10-01 15:04:09,563 Attempting refresh to obtain initial access_token
INFO 2022-10-01 15:04:09,597 Refreshing access_token
WARNING 2022-10-01 15:04:11,021 Not Found: /static/css/base.css
WARNING 2022-10-01 15:04:11,035 Not Found: /static/images/logo_canal.png
WARNING 2022-10-01 15:04:11,056 Not Found: /static/css/base.css
INFO 2022-10-01 15:07:30,947 file_cache is only supported with oauth2client<4.0.0
INFO 2022-10-01 15:07:31,118 Attempting refresh to obtain initial access_token
INFO 2022-10-01 15:07:31,152 Refreshing access_token
WARNING 2022-10-01 15:07:32,853 Not Found: /static/css/base.css
WARNING 2022-10-01 15:07:32,862 Not Found: /static/images/logo_canal.png
WARNING 2022-10-01 15:07:32,873 Not Found: /static/css/base.css
INFO 2022-10-01 15:09:18,476 file_cache is only supported with oauth2client<4.0.0
INFO 2022-10-01 15:09:18,659 Attempting refresh to obtain initial access_token
INFO 2022-10-01 15:09:18,693 Refreshing access_token
WARNING 2022-10-01 15:09:20,250 Not Found: /static/css/base.css
WARNING 2022-10-01 15:09:20,259 Not Found: /static/images/logo_canal.png
WARNING 2022-10-01 15:09:20,269 Not Found: /static/css/base.css
INFO 2022-10-01 15:17:48,035 file_cache is only supported with oauth2client<4.0.0
INFO 2022-10-01 15:17:48,206 Attempting refresh to obtain initial access_token
INFO 2022-10-01 15:17:48,241 Refreshing access_token
WARNING 2022-10-01 15:17:49,963 Not Found: /static/css/base.css
WARNING 2022-10-01 15:17:50,170 Not Found: /static/images/logo_canal.png
WARNING 2022-10-01 15:17:50,212 Not Found: /static/css/base.css
INFO 2022-10-01 15:20:23,444 file_cache is only supported with oauth2client<4.0.0
INFO 2022-10-01 15:20:23,625 Attempting refresh to obtain initial access_token
INFO 2022-10-01 15:20:23,658 Refreshing access_token
WARNING 2022-10-01 15:20:25,358 Not Found: /static/css/base.css
WARNING 2022-10-01 15:20:25,384 Not Found: /static/css/base.css
WARNING 2022-10-01 15:20:25,400 Not Found: /static/images/logo_canal.png
INFO 2022-10-01 15:22:27,427 file_cache is only supported with oauth2client<4.0.0
INFO 2022-10-01 15:22:27,602 Attempting refresh to obtain initial access_token
INFO 2022-10-01 15:22:27,640 Refreshing access_token
WARNING 2022-10-01 15:22:29,068 Not Found: /static/css/base.css
WARNING 2022-10-01 15:22:29,086 Not Found: /static/images/logo_canal.png
WARNING 2022-10-01 15:22:29,150 Not Found: /static/css/base.css
INFO 2022-10-01 15:27:07,508 file_cache is only supported with oauth2client<4.0.0
INFO 2022-10-01 15:27:07,715 Attempting refresh to obtain initial access_token
INFO 2022-10-01 15:27:07,754 Refreshing access_token
ERROR 2022-10-01 15:27:09,642 Internal Server Error: /canal_service/
Traceback (most recent call last):
  File "/usr/local/lib/python3.9/site-packages/django/core/handlers/exception.py", line 47, in inner
    response = get_response(request)
  File "/usr/local/lib/python3.9/site-packages/django/core/handlers/base.py", line 204, in _get_response
    response = response.render()
  File "/usr/local/lib/python3.9/site-packages/django/template/response.py", line 105, in render
    self.content = self.rendered_content
  File "/usr/local/lib/python3.9/site-packages/django/template/response.py", line 83, in rendered_content
    return template.render(context, self._request)
  File "/usr/local/lib/python3.9/site-packages/django/template/backends/django.py", line 61, in render
    return self.template.render(context)
  File "/usr/local/lib/python3.9/site-packages/django/template/base.py", line 170, in render
    return self._render(context)
  File "/usr/local/lib/python3.9/site-packages/django/test/utils.py", line 100, in instrumented_test_render
    return self.nodelist.render(context)
  File "/usr/local/lib/python3.9/site-packages/django/template/base.py", line 938, in render
    bit = node.render_annotated(context)
  File "/usr/local/lib/python3.9/site-packages/django/template/base.py", line 905, in render_annotated
    return self.render(context)
  File "/usr/local/lib/python3.9/site-packages/django/template/loader_tags.py", line 150, in render
    return compiled_parent._render(context)
  File "/usr/local/lib/python3.9/site-packages/django/test/utils.py", line 100, in instrumented_test_render
    return self.nodelist.render(context)
  File "/usr/local/lib/python3.9/site-packages/django/template/base.py", line 938, in render
    bit = node.render_annotated(context)
  File "/usr/local/lib/python3.9/site-packages/django/template/base.py", line 905, in render_annotated
    return self.render(context)
  File "/usr/local/lib/python3.9/site-packages/django/templatetags/static.py", line 106, in render
    url = self.url(context)
  File "/usr/local/lib/python3.9/site-packages/django/templatetags/static.py", line 103, in url
    return self.handle_simple(path)
  File "/usr/local/lib/python3.9/site-packages/django/templatetags/static.py", line 118, in handle_simple
    return staticfiles_storage.url(path)
  File "/usr/local/lib/python3.9/site-packages/django/utils/functional.py", line 246, in inner
    self._setup()
  File "/usr/local/lib/python3.9/site-packages/django/contrib/staticfiles/storage.py", line 438, in _setup
    self._wrapped = get_storage_class(settings.STATICFILES_STORAGE)()
  File "/usr/local/lib/python3.9/site-packages/django/contrib/staticfiles/storage.py", line 28, in __init__
    check_settings(base_url)
  File "/usr/local/lib/python3.9/site-packages/django/contrib/staticfiles/utils.py", line 53, in check_settings
    raise ImproperlyConfigured("The MEDIA_URL and STATIC_URL "
django.core.exceptions.ImproperlyConfigured: The MEDIA_URL and STATIC_URL settings must have different values
INFO 2022-10-01 15:29:16,859 file_cache is only supported with oauth2client<4.0.0
INFO 2022-10-01 15:29:17,070 Attempting refresh to obtain initial access_token
INFO 2022-10-01 15:29:17,106 Refreshing access_token
WARNING 2022-10-01 15:29:18,555 Not Found: /static/css/base.css
WARNING 2022-10-01 15:29:18,796 Not Found: /static/images/logo_canal.png
WARNING 2022-10-01 15:29:18,824 Not Found: /static/css/base.css
INFO 2022-10-01 15:34:37,673 file_cache is only supported with oauth2client<4.0.0
INFO 2022-10-01 15:34:37,881 Attempting refresh to obtain initial access_token
INFO 2022-10-01 15:34:37,915 Refreshing access_token
WARNING 2022-10-01 15:34:39,753 Not Found: /static/css/base.css
WARNING 2022-10-01 15:34:39,770 Not Found: /static/images/logo_canal.png
WARNING 2022-10-01 15:34:39,838 Not Found: /static/css/base.css
INFO 2022-10-01 15:36:24,961 file_cache is only supported with oauth2client<4.0.0
INFO 2022-10-01 15:36:25,125 Attempting refresh to obtain initial access_token
INFO 2022-10-01 15:36:25,158 Refreshing access_token
WARNING 2022-10-01 15:36:26,143 Not Found: /static/css/base.css
WARNING 2022-10-01 15:36:26,157 Not Found: /static/images/logo_canal.png
WARNING 2022-10-01 15:36:26,172 Not Found: /static/css/base.css
INFO 2022-10-01 15:48:00,289 file_cache is only supported with oauth2client<4.0.0
INFO 2022-10-01 15:48:00,459 Attempting refresh to obtain initial access_token
INFO 2022-10-01 15:48:00,492 Refreshing access_token
INFO 2022-10-02 07:41:49,940 file_cache is only supported with oauth2client<4.0.0
INFO 2022-10-02 07:41:50,140 Attempting refresh to obtain initial access_token
INFO 2022-10-02 07:41:50,174 Refreshing access_token
INFO 2022-10-02 09:39:30,063 file_cache is only supported with oauth2client<4.0.0
INFO 2022-10-02 09:39:30,342 Attempting refresh to obtain initial access_token
INFO 2022-10-02 09:39:30,378 Refreshing access_token
INFO 2022-10-02 09:39:59,629 file_cache is only supported with oauth2client<4.0.0
INFO 2022-10-02 09:39:59,801 Attempting refresh to obtain initial access_token
INFO 2022-10-02 09:39:59,834 Refreshing access_token
INFO 2022-10-02 09:40:32,264 file_cache is only supported with oauth2client<4.0.0
INFO 2022-10-02 09:40:32,425 Attempting refresh to obtain initial access_token
INFO 2022-10-02 09:40:32,470 Refreshing access_token
INFO 2022-10-02 09:41:03,051 file_cache is only supported with oauth2client<4.0.0
INFO 2022-10-02 09:41:03,210 Attempting refresh to obtain initial access_token
INFO 2022-10-02 09:41:03,244 Refreshing access_token
INFO 2022-10-02 09:41:48,329 file_cache is only supported with oauth2client<4.0.0
INFO 2022-10-02 09:41:48,509 Attempting refresh to obtain initial access_token
INFO 2022-10-02 09:41:48,543 Refreshing access_token
ERROR 2022-10-02 09:55:00,339 Internal Server Error: /canal_service/
Traceback (most recent call last):
  File "/usr/local/lib/python3.9/site-packages/django/core/handlers/exception.py", line 47, in inner
    response = get_response(request)
  File "/usr/local/lib/python3.9/site-packages/django/core/handlers/base.py", line 167, in _get_response
    callback, callback_args, callback_kwargs = self.resolve_request(request)
  File "/usr/local/lib/python3.9/site-packages/django/core/handlers/base.py", line 290, in resolve_request
    resolver_match = resolver.resolve(request.path_info)
  File "/usr/local/lib/python3.9/site-packages/django/urls/resolvers.py", line 556, in resolve
    for pattern in self.url_patterns:
  File "/usr/local/lib/python3.9/site-packages/django/utils/functional.py", line 48, in __get__
    res = instance.__dict__[self.name] = self.func(instance)
  File "/usr/local/lib/python3.9/site-packages/django/urls/resolvers.py", line 598, in url_patterns
    patterns = getattr(self.urlconf_module, "urlpatterns", self.urlconf_module)
  File "/usr/local/lib/python3.9/site-packages/django/utils/functional.py", line 48, in __get__
    res = instance.__dict__[self.name] = self.func(instance)
  File "/usr/local/lib/python3.9/site-packages/django/urls/resolvers.py", line 591, in urlconf_module
    return import_module(self.urlconf_name)
  File "/usr/local/lib/python3.9/importlib/__init__.py", line 127, in import_module
    return _bootstrap._gcd_import(name[level:], package, level)
  File "<frozen importlib._bootstrap>", line 1030, in _gcd_import
  File "<frozen importlib._bootstrap>", line 1007, in _find_and_load
  File "<frozen importlib._bootstrap>", line 986, in _find_and_load_unlocked
  File "<frozen importlib._bootstrap>", line 680, in _load_unlocked
  File "<frozen importlib._bootstrap_external>", line 850, in exec_module
  File "<frozen importlib._bootstrap>", line 228, in _call_with_frames_removed
  File "/code/КаналсервисTest/urls.py", line 24, in <module>
    path('', include('table_app.urls')),
  File "/usr/local/lib/python3.9/site-packages/django/urls/conf.py", line 34, in include
    urlconf_module = import_module(urlconf_module)
  File "/usr/local/lib/python3.9/importlib/__init__.py", line 127, in import_module
    return _bootstrap._gcd_import(name[level:], package, level)
  File "<frozen importlib._bootstrap>", line 1030, in _gcd_import
  File "<frozen importlib._bootstrap>", line 1007, in _find_and_load
  File "<frozen importlib._bootstrap>", line 986, in _find_and_load_unlocked
  File "<frozen importlib._bootstrap>", line 680, in _load_unlocked
  File "<frozen importlib._bootstrap_external>", line 850, in exec_module
  File "<frozen importlib._bootstrap>", line 228, in _call_with_frames_removed
  File "/code/table_app/urls.py", line 2, in <module>
    from .views import TablePageView
  File "/code/table_app/views.py", line 4, in <module>
    from table_app.scripts import get_document_data, get_today_dollar_rate, get_schedule_data_and_data_base_update
  File "/code/table_app/scripts.py", line 8, in <module>
    from models import ResultTable
ModuleNotFoundError: No module named 'models'
ERROR 2022-10-02 09:55:01,088 Internal Server Error: /favicon.ico
Traceback (most recent call last):
  File "/usr/local/lib/python3.9/site-packages/django/core/handlers/exception.py", line 47, in inner
    response = get_response(request)
  File "/usr/local/lib/python3.9/site-packages/django/utils/deprecation.py", line 116, in __call__
    response = self.process_request(request)
  File "/usr/local/lib/python3.9/site-packages/django/middleware/common.py", line 53, in process_request
    if self.should_redirect_with_slash(request):
  File "/usr/local/lib/python3.9/site-packages/django/middleware/common.py", line 70, in should_redirect_with_slash
    if not is_valid_path(request.path_info, urlconf):
  File "/usr/local/lib/python3.9/site-packages/django/urls/base.py", line 153, in is_valid_path
    return resolve(path, urlconf)
  File "/usr/local/lib/python3.9/site-packages/django/urls/base.py", line 24, in resolve
    return get_resolver(urlconf).resolve(path)
  File "/usr/local/lib/python3.9/site-packages/django/urls/resolvers.py", line 556, in resolve
    for pattern in self.url_patterns:
  File "/usr/local/lib/python3.9/site-packages/django/utils/functional.py", line 48, in __get__
    res = instance.__dict__[self.name] = self.func(instance)
  File "/usr/local/lib/python3.9/site-packages/django/urls/resolvers.py", line 598, in url_patterns
    patterns = getattr(self.urlconf_module, "urlpatterns", self.urlconf_module)
  File "/usr/local/lib/python3.9/site-packages/django/utils/functional.py", line 48, in __get__
    res = instance.__dict__[self.name] = self.func(instance)
  File "/usr/local/lib/python3.9/site-packages/django/urls/resolvers.py", line 591, in urlconf_module
    return import_module(self.urlconf_name)
  File "/usr/local/lib/python3.9/importlib/__init__.py", line 127, in import_module
    return _bootstrap._gcd_import(name[level:], package, level)
  File "<frozen importlib._bootstrap>", line 1030, in _gcd_import
  File "<frozen importlib._bootstrap>", line 1007, in _find_and_load
  File "<frozen importlib._bootstrap>", line 986, in _find_and_load_unlocked
  File "<frozen importlib._bootstrap>", line 680, in _load_unlocked
  File "<frozen importlib._bootstrap_external>", line 850, in exec_module
  File "<frozen importlib._bootstrap>", line 228, in _call_with_frames_removed
  File "/code/КаналсервисTest/urls.py", line 24, in <module>
    path('', include('table_app.urls')),
  File "/usr/local/lib/python3.9/site-packages/django/urls/conf.py", line 34, in include
    urlconf_module = import_module(urlconf_module)
  File "/usr/local/lib/python3.9/importlib/__init__.py", line 127, in import_module
    return _bootstrap._gcd_import(name[level:], package, level)
  File "<frozen importlib._bootstrap>", line 1030, in _gcd_import
  File "<frozen importlib._bootstrap>", line 1007, in _find_and_load
  File "<frozen importlib._bootstrap>", line 986, in _find_and_load_unlocked
  File "<frozen importlib._bootstrap>", line 680, in _load_unlocked
  File "<frozen importlib._bootstrap_external>", line 850, in exec_module
  File "<frozen importlib._bootstrap>", line 228, in _call_with_frames_removed
  File "/code/table_app/urls.py", line 2, in <module>
    from .views import TablePageView
  File "/code/table_app/views.py", line 4, in <module>
    from table_app.scripts import get_document_data, get_today_dollar_rate, get_schedule_data_and_data_base_update
  File "/code/table_app/scripts.py", line 8, in <module>
    from models import ResultTable
ModuleNotFoundError: No module named 'models'
INFO 2022-10-02 09:56:09,839 file_cache is only supported with oauth2client<4.0.0
INFO 2022-10-02 09:56:10,006 Attempting refresh to obtain initial access_token
INFO 2022-10-02 09:56:10,041 Refreshing access_token
INFO 2022-10-02 09:58:34,645 file_cache is only supported with oauth2client<4.0.0
INFO 2022-10-02 09:58:34,826 Attempting refresh to obtain initial access_token
INFO 2022-10-02 09:58:34,860 Refreshing access_token
INFO 2022-10-02 10:01:38,846 file_cache is only supported with oauth2client<4.0.0
INFO 2022-10-02 10:01:39,048 Attempting refresh to obtain initial access_token
INFO 2022-10-02 10:01:39,082 Refreshing access_token
INFO 2022-10-02 10:24:18,587 file_cache is only supported with oauth2client<4.0.0
INFO 2022-10-02 10:24:18,771 Attempting refresh to obtain initial access_token
INFO 2022-10-02 10:24:18,806 Refreshing access_token
INFO 2022-10-02 10:27:05,544 file_cache is only supported with oauth2client<4.0.0
INFO 2022-10-02 10:27:05,715 Attempting refresh to obtain initial access_token
INFO 2022-10-02 10:27:05,750 Refreshing access_token
INFO 2022-10-02 10:35:39,493 file_cache is only supported with oauth2client<4.0.0
INFO 2022-10-02 10:35:39,666 Attempting refresh to obtain initial access_token
INFO 2022-10-02 10:35:39,701 Refreshing access_token
INFO 2022-10-02 10:38:52,752 file_cache is only supported with oauth2client<4.0.0
INFO 2022-10-02 10:38:52,919 Attempting refresh to obtain initial access_token
INFO 2022-10-02 10:38:52,953 Refreshing access_token
ERROR 2022-10-02 11:42:02,883 Invalid HTTP_HOST header: '192.168.100.71:8000'. You may need to add '192.168.100.71' to ALLOWED_HOSTS.
WARNING 2022-10-02 11:42:03,677 Bad Request: /
INFO 2022-10-02 11:51:57,805 file_cache is only supported with oauth2client<4.0.0
INFO 2022-10-02 11:51:58,115 Attempting refresh to obtain initial access_token
INFO 2022-10-02 11:51:58,161 Refreshing access_token
INFO 2022-10-02 11:53:15,873 file_cache is only supported with oauth2client<4.0.0
INFO 2022-10-02 11:53:16,079 Attempting refresh to obtain initial access_token
INFO 2022-10-02 11:53:16,216 Refreshing access_token
INFO 2022-10-02 11:54:06,063 file_cache is only supported with oauth2client<4.0.0
INFO 2022-10-02 11:54:06,240 Attempting refresh to obtain initial access_token
INFO 2022-10-02 11:54:06,280 Refreshing access_token
INFO 2022-10-02 11:54:43,038 file_cache is only supported with oauth2client<4.0.0
INFO 2022-10-02 11:54:43,236 Attempting refresh to obtain initial access_token
INFO 2022-10-02 11:54:43,271 Refreshing access_token
INFO 2022-10-02 11:55:46,771 file_cache is only supported with oauth2client<4.0.0
INFO 2022-10-02 11:55:46,929 Attempting refresh to obtain initial access_token
INFO 2022-10-02 11:55:46,964 Refreshing access_token
